<message>
you were asked to translate the given python function to rust and execute your response and get some error message.
Fix the bug in your previous response according to error message, python function, rust function signature, rust function dependencies(including function and variable dependencies), and data type declarations and rust function dependency libraries I provide(delimited with XML tags).
Only response the function results.
<previous response>
b'impl PublicKey {\n    pub fn verify(&self, msg: &[u8], sig: &[u8]) -> bool {\n        let verify_key = self.to_bytes();\n        match ed25519::VerifyingKey::from_bytes(&verify_key).verify(msg, sig) {\n            Ok(_) => true,\n            Err(_) => false,\n        }\n    }\n}'
</previous response>
<error message>
Compiling libp2p-identity v0.2.9 (/home/k/ogs_PHD/LLM4SE/2Rust_projects/auto_get_functionPair/projects/libp2p/rust/identity)
error[E0599]: no method named `verify` found for enum `Result` in the current scope
   --> identity/src/ed25519.rs:149:62
    |
149 |         match ed25519::VerifyingKey::from_bytes(&verify_key).verify(msg, sig) {
    |                                                              ^^^^^^ method not found in `Result<VerifyingKey, Error>`
    |
note: the method `verify` exists on the type `VerifyingKey`
   --> /home/k/.cargo/registry/src/index.crates.io-6f17d22bba15001f/signature-2.1.0/src/verifier.rs:14:5
    |
14  |     fn verify(&self, msg: &[u8], signature: &S) -> Result<(), Error>;
    |     ^^^^^^^^^^^^^^^^^^^^^^^^^^^^^^^^^^^^^^^^^^^^^^^^^^^^^^^^^^^^^^^^^
help: consider using `Result::expect` to unwrap the `VerifyingKey` value, panicking if the value is a `Result::Err`
    |
149 |         match ed25519::VerifyingKey::from_bytes(&verify_key).expect("REASON").verify(msg, sig) {
    |                                                             +++++++++++++++++

warning: unused import: `Verifier`
  --> identity/src/ed25519.rs:29:51
   |
29 | use ed25519_dalek::{self as ed25519, Signer as _, Verifier as _};
   |                                                   ^^^^^^^^
   |
   = note: `#[warn(unused_imports)]` on by default

For more information about this error, try `rustc --explain E0599`.
warning: `libp2p-identity` (lib) generated 1 warning
error: could not compile `libp2p-identity` (lib) due to 1 previous error; 1 warning emitted
warning: build failed, waiting for other jobs to finish...
warning: `libp2p-identity` (lib test) generated 1 warning (1 duplicate)
error: could not compile `libp2p-identity` (lib test) due to 1 previous error; 1 warning emitted
</error message>
<python function>
def verify(self, data: bytes, signature: bytes) -> bool:
        verify_key = VerifyKey(self.to_bytes())
        try:
            verify_key.verify(data, signature)
        except BadSignatureError:
            return False
        return True
</python function>
<rust function signature>
pub fn verify(&self, msg: &[u8], sig: &[u8]) -> bool 
</rust function signature>
<rust function dependencies, and data type declarations>
pub struct PublicKey(ed25519::VerifyingKey);


</rust function dependencies and data type declarations>
<rust function dependency libraries>
use super::error::DecodingError;
use core::cmp;
use core::fmt;
use core::hash;
use ed25519_dalek::{self as ed25519, Signer as _, Verifier as _};
use zeroize::Zeroize;
use super::*;
use quickcheck::*;

</rust function dependency libraries>

</message>
<reapir response>
Here is the corrected Rust function:

```rust
impl PublicKey {
    pub fn verify(&self, msg: &[u8], sig: &[u8]) -> bool {
        let verify_key = self.to_bytes();
        match ed25519::VerifyingKey::from_bytes(&verify_key) {
            Ok(key) => key.verify(msg, sig),
            Err(_) => false,
        }
    }
}
```

Explanation of the changes:

1. The `verify` method is called directly on the `VerifyingKey` instance, rather than trying to call it on the `Result` enum.
2. The `match` statement is used to handle the `Result` returned by `from_bytes`, and the `Ok` branch is used to call the `verify` method on the `VerifyingKey` instance.
3. The `Err` branch is used to return `false` if the `from_bytes` method returns an error.</reapir response>